server/tests/fixtures/hl_dual_validator/golden/parser_stream_tob.jsonl
{"channel":"marketdata","channel_id":0,"reset_count":0,"seq":0,"ts":"1970-01-01T00:00:00Z","type":"channel_reset"}
{"channel":"refdata","channel_id":0,"reset_count":0,"seq":0,"ts":"1970-01-01T00:00:00Z","type":"channel_reset"}
{"channel":"refdata","channel_id":0,"fields":{"asset_class":1,"contract_value":0,"leg1":"BTC","leg2":"","lot_size":0,"manifest_seq":1,"market_model":1,"price_bound":0,"price_exponent":-1,"qty_exponent":-8,"settle_type":0,"tick_size":0},"reset_count":0,"seq":0,"symbol":"BTC","ts":"1970-01-01T00:00:00Z","type":"instrument_definition"}
{"channel":"refdata","channel_id":0,"fields":{"instrument_count":1,"manifest_seq":1},"reset_count":0,"seq":0,"ts":"1970-01-01T00:00:00Z","type":"manifest_summary"}
{"channel":"marketdata","channel_id":0,"fields":{"ask_n":49,"ask_price":81308,"ask_px_raw":813080,"ask_qty":6.08207,"ask_source_count":49,"ask_sz_raw":608207000,"bid_n":4,"bid_price":81307,"bid_px_raw":813070,"bid_qty":0.20195,"bid_source_count":4,"bid_sz_raw":20195000,"price_exponent":-1,"qty_exponent":-8,"send_timestamp_ns":0,"snapshot":false,"source_id":1,"source_ts_ms":0,"source_ts_ns":0,"update_flags":3},"reset_count":0,"seq":0,"symbol":"BTC","ts":"1970-01-01T00:00:00Z","type":"quote"}
{"channel":"marketdata","channel_id":0,"fields":{"ask_n":49,"ask_price":81308,"ask_px_raw":813080,"ask_qty":6.08174,"ask_source_count":49,"ask_sz_raw":608174000,"bid_n":4,"bid_price":81307,"bid_px_raw":813070,"bid_qty":0.20195,"bid_source_count":4,"bid_sz_raw":20195000,"price_exponent":-1,"qty_exponent":-8,"send_timestamp_ns":0,"snapshot":false,"source_id":1,"source_ts_ms":1778002753024,"source_ts_ns":1778002753024000000,"update_flags":3},"reset_count":0,"seq":0,"symbol":"BTC","ts":"2026-05-05T17:39:13.024Z","type":"quote"}
{"channel":"marketdata","channel_id":0,"fields":{"ask_n":49,"ask_price":81308,"ask_px_raw":813080,"ask_qty":6.08174,"ask_source_count":49,"ask_sz_raw":608174000,"bid_n":4,"bid_price":81307,"bid_px_raw":813070,"bid_qty":0.20195,"bid_source_count":4,"bid_sz_raw":20195000,"price_exponent":-1,"qty_exponent":-8,"send_timestamp_ns":0,"snapshot":false,"source_id":1,"source_ts_ms":1778002753024,"source_ts_ns":1778002753024000000,"update_flags":3},"reset_count":0,"seq":0,"symbol":"BTC","ts":"2026-05-05T17:39:13.024Z","type":"quote"}
{"channel":"marketdata","channel_id":0,"fields":{"ask_n":49,"ask_price":81308,"ask_px_raw":813080,"ask_qty":6.08174,"ask_source_count":49,"ask_sz_raw":608174000,"bid_n":4,"bid_price":81307,"bid_px_raw":813070,"bid_qty":0.20195,"bid_source_count":4,"bid_sz_raw":20195000,"price_exponent":-1,"qty_exponent":-8,"send_timestamp_ns":0,"snapshot":false,"source_id":1,"source_ts_ms":1778002753024,"source_ts_ns":1778002753024000000,"update_flags":3},"reset_count":0,"seq":0,"symbol":"BTC","ts":"2026-05-05T17:39:13.024Z","type":"quote"}
{"channel":"marketdata","channel_id":0,"fields":{"ask_n":49,"ask_price":81308,"ask_px_raw":813080,"ask_qty":6.08174,"ask_source_count":49,"ask_sz_raw":608174000,"bid_n":4,"bid_price":81307,"bid_px_raw":813070,"bid_qty":0.20195,"bid_source_count":4,"bid_sz_raw":20195000,"price_exponent":-1,"qty_exponent":-8,"send_timestamp_ns":0,"snapshot":false,"source_id":1,"source_ts_ms":1778002753024,"source_ts_ns":1778002753024000000,"update_flags":3},"reset_count":0,"seq":0,"symbol":"BTC","ts":"2026-05-05T17:39:13.024Z","type":"quote"}
{"channel":"marketdata","channel_id":0,"fields":{"ask_n":49,"ask_price":81308,"ask_px_raw":813080,"ask_qty":6.08174,"ask_source_count":49,"ask_sz_raw":608174000,"bid_n":4,"bid_price":81307,"bid_px_raw":813070,"bid_qty":0.20195,"bid_source_count":4,"bid_sz_raw":20195000,"price_exponent":-1,"qty_exponent":-8,"send_timestamp_ns":0,"snapshot":false,"source_id":1,"source_ts_ms":1778002753024,"source_ts_ns":1778002753024000000,"update_flags":3},"reset_count":0,"seq":0,"symbol":"BTC","ts":"2026-05-05T17:39:13.024Z","type":"quote"}
{"channel":"marketdata","channel_id":0,"fields":{"ask_n":49,"ask_price":81308,"ask_px_raw":813080,"ask_qty":6.08174,"ask_source_count":49,"ask_sz_raw":608174000,"bid_n":4,"bid_price":81307,"bid_px_raw":813070,"bid_qty":0.20195,"bid_source_count":4,"bid_sz_raw":20195000,"price_exponent":-1,"qty_exponent":-8,"send_timestamp_ns":0,"snapshot":false,"source_id":1,"source_ts_ms":1778002753024,"source_ts_ns":1778002753024000000,"update_flags":3},"reset_count":0,"seq":0,"symbol":"BTC","ts":"2026-05-05T17:39:13.024Z","type":"quote"}
{"channel":"marketdata","channel_id":0,"fields":{"ask_n":49,"ask_price":81308,"ask_px_raw":813080,"ask_qty":6.08174,"ask_source_count":49,"ask_sz_raw":608174000,"bid_n":4,"bid_price":81307,"bid_px_raw":813070,"bid_qty":0.20195,"bid_source_count":4,"bid_sz_raw":20195000,"price_exponent":-1,"qty_exponent":-8,"send_timestamp_ns":0,"snapshot":false,"source_id":1,"source_ts_ms":1778002753024,"source_ts_ns":1778002753024000000,"update_flags":3},"reset_count":0,"seq":0,"symbol":"BTC","ts":"2026-05-05T17:39:13.024Z","type":"quote"}
{"channel":"marketdata","channel_id":0,"fields":{"ask_n":49,"ask_price":81308,"ask_px_raw":813080,"ask_qty":6.08174,"ask_source_count":49,"ask_sz_raw":608174000,"bid_n":4,"bid_price":81307,"bid_px_raw":813070,"bid_qty":0.20195,"bid_source_count":4,"bid_sz_raw":20195000,"price_exponent":-1,"qty_exponent":-8,"send_timestamp_ns":0,"snapshot":false,"source_id":1,"source_ts_ms":1778002753024,"source_ts_ns":1778002753024000000,"update_flags":3},"reset_count":0,"seq":0,"symbol":"BTC","ts":"2026-05-05T17:39:13.024Z","type":"quote"}
{"channel":"marketdata","channel_id":0,"fields":{"ask_n":49,"ask_price":81308,"ask_px_raw":813080,"ask_qty":6.08174,"ask_source_count":49,"ask_sz_raw":608174000,"bid_n":4,"bid_price":81307,"bid_px_raw":813070,"bid_qty":0.20195,"bid_source_count":4,"bid_sz_raw":20195000,"price_exponent":-1,"qty_exponent":-8,"send_timestamp_ns":0,"snapshot":false,"source_id":1,"source_ts_ms":1778002753024,"source_ts_ns":1778002753024000000,"update_flags":3},"reset_count":0,"seq":0,"symbol":"BTC","ts":"2026-05-05T17:39:13.024Z","type":"quote"}
{"channel":"marketdata","channel_id":0,"fields":{"ask_n":49,"ask_price":81308,"ask_px_raw":813080,"ask_qty":6.08174,"ask_source_count":49,"ask_sz_raw":608174000,"bid_n":4,"bid_price":81307,"bid_px_raw":813070,"bid_qty":0.20195,"bid_source_count":4,"bid_sz_raw":20195000,"price_exponent":-1,"qty_exponent":-8,"send_timestamp_ns":0,"snapshot":false,"source_id":1,"source_ts_ms":1778002753024,"source_ts_ns":1778002753024000000,"update_flags":3},"reset_count":0,"seq":0,"symbol":"BTC","ts":"2026-05-05T17:39:13.024Z","type":"quote"}
{"channel":"marketdata","channel_id":0,"fields":{"ask_n":49,"ask_price":81308,"ask_px_raw":813080,"ask_qty":6.08174,"ask_source_count":49,"ask_sz_raw":608174000,"bid_n":4,"bid_price":81307,"bid_px_raw":813070,"bid_qty":0.20195,"bid_source_count":4,"bid_sz_raw":20195000,"price_exponent":-1,"qty_exponent":-8,"send_timestamp_ns":0,"snapshot":false,"source_id":1,"source_ts_ms":1778002753024,"source_ts_ns":1778002753024000000,"update_flags":3},"reset_count":0,"seq":0,"symbol":"BTC","ts":"2026-05-05T17:39:13.024Z","type":"quote"}
{"channel":"marketdata","channel_id":0,"fields":{"ask_n":50,"ask_price":81308,"ask_px_raw":813080,"ask_qty":6.69664,"ask_source_count":50,"ask_sz_raw":669664000,"bid_n":4,"bid_price":81307,"bid_px_raw":813070,"bid_qty":0.20195,"bid_source_count":4,"bid_sz_raw":20195000,"price_exponent":-1,"qty_exponent":-8,"send_timestamp_ns":0,"snapshot":false,"source_id":1,"source_ts_ms":1778002753024,"source_ts_ns":1778002753024000000,"update_flags":3},"reset_count":0,"seq":0,"symbol":"BTC","ts":"2026-05-05T17:39:13.024Z","type":"quote"}
{"channel":"marketdata","channel_id":0,"fields":{"ask_n":50,"ask_price":81308,"ask_px_raw":813080,"ask_qty":6.69664,"ask_source_count":50,"ask_sz_raw":669664000,"bid_n":4,"bid_price":81307,"bid_px_raw":813070,"bid_qty":0.20195,"bid_source_count":4,"bid_sz_raw":20195000,"price_exponent":-1,"qty_exponent":-8,"send_timestamp_ns":0,"snapshot":false,"source_id":1,"source_ts_ms":1778002753024,"source_ts_ns":1778002753024000000,"update_flags":3},"reset_count":0,"seq":0,"symbol":"BTC","ts":"2026-05-05T17:39:13.024Z","type":"quote"}
